Workbook

Sheet Assumptions
A1: Mazou Financial Model — Assumptions
A2: All blue cells are adjustable inputs. Change them to run scenarios.
A4: CUSTOMER GROWTH | B4: Value | C4: Unit | F4: Notes
A5: Launch customers (Month 1) | B5: 5 | C5: customers | F5: Beta cohort at launch
A6: Monthly customer growth rate (M1-6) | B6: 0.25 | F6: High growth — early traction phase
A7: Monthly customer growth rate (M7-12) | B7: 0.2 | F7: Stabilising but still strong
A8: Monthly customer growth rate (M13-24) | B8: 0.15 | F8: Scale-up phase
A9: Monthly customer growth rate (M25-36) | B9: 0.1 | F9: Mature growth
A10: Monthly churn rate | B10: 0.03 | F10: Developer platform typical: 2-5%
A12: REVENUE — LLM API GATEWAY
A13: Avg monthly API spend per customer (start) | B13: 150000 | C13: ₦/mo | F13: ~$94 at ₦1,600/$
A14: Monthly ARPU growth rate | B14: 0.03 | F14: Usage expansion as customers adopt more models
A15: Take rate on API passthrough | B15: 0.08 | F15: 8% margin on API spend — industry 5-15%
A16: Smart Routing savings share | B16: 0.2 | F16: Mazou keeps 20% of savings generated for customer
A17: Avg routing savings as % of spend | B17: 0.15 | F17: Smart routing saves ~15% of a customer's total LLM spend
A19: REVENUE — AGENT SERVICES (BYOK)
A20: Month agent services launch | B20: 10 | F20: Q4 2026 — Coinbase wallet integration
A21: % of customers adopting agent services | B21: 0.15 | F21: Early adopters connecting Coinbase/Stripe keys
A22: Monthly agent service adoption growth | B22: 0.05 | F22: Grows 5% per month as more services integrate
A23: Avg agent service spend per adopter (start) | B23: 50000 | C23: ₦/mo | F23: ~$31 — wallet txns, search APIs, commerce
A24: Agent service ARPU growth rate | B24: 0.05 | F24: Faster growth as agents do more
A25: Take rate on agent service passthrough | B25: 0.05 | F25: Lower take rate — visibility/convenience is the value
A27: REVENUE — USDT / CRYPTO PAYMENTS
A28: Month USDT funding launches | B28: 10 | F28: Alongside agent wallet launch
A29: % of customers funding in USDT | B29: 0.1 | F29: Cross-border teams, crypto-native devs
A30: FX spread on USDT→NGN conversion | B30: 0.015 | F30: 1.5% spread — competitive vs black market
A32: COSTS
A33: Cloud infrastructure (Month 1) | B33: 800000 | C33: ₦/mo | F33: ~$500/mo — servers, CDN, monitoring
A34: Infra cost monthly growth rate | B34: 0.08 | F34: Scales with traffic but with economies of scale
A35: Team size at launch (headcount) | B35: 3 | F35: Founder + 2 engineers
A36: Avg monthly salary per person | B36: 1200000 | C36: ₦/mo | F36: ~$750/mo avg across team
A37: Hiring: new person every N months | B37: 4 | C37: months | F37: 1 new hire every 4 months
A38: Marketing spend (Month 1) | B38: 200000 | C38: ₦/mo | F38: ~$125/mo — content, dev community, events
A39: Marketing monthly growth rate | B39: 0.1 | F39: Ramp up as revenue grows
A40: Payment processing fee | B40: 0.015 | F40: Paystack charges ~1.5%
A41: Other OpEx (Month 1) | B41: 300000 | C41: ₦/mo | F41: Legal, tools, subscriptions, misc
A42: Other OpEx growth rate | B42: 0.05
A44: FX & OTHER
A45: NGN/USD exchange rate | B45: 1600 | C45: ₦/$ | F45: Used for USD equivalent display
A47: FUNDRAISING
...

Sheet Monthly P&L
A1: Mazou — Monthly P&L (36 Months)
A2: All values in ₦ (Nigerian Naira)
B4: M1 | C4: M2 | D4: M3 | E4: M4 | F4: M5 | G4: M6 | H4: M7 | I4: M8 | J4: M9 | K4: M10 | L4: M11 | M4: M12 | N4: M13 | O4: M14 | P4: M15 | Q4: M16 | R4: M17 | S4: M18 | T4: M19 | U4: M20 | V4: M21 | W4: M22 | X4: M23 | Y4: M24 | Z4: M25 | AA4: M26 | AB4: M27 | AC4: M28 | AD4: M29 | AE4: M30 | AF4: M31 | AG4: M32 | AH4: M33 | AI4: M34 | AJ4: M35 | AK4: M36
A6: CUSTOMERS
A7: New customers | B7: =Assumptions!B5 -> 5 | C7: =ROUND(B9*IF(2<=6,Assumptions!B6,IF(2<=12,Assumptions!B7,IF(2<=24,Assumptions!B8,Assumptions!B9))),0) -> 1 | D7: =ROUND(C9*IF(3<=6,Assumptions!B6,IF(3<=12,Assumptions!B7,IF(3<=24,Assumptions!B8,Assumptions!B9))),0) -> 2 | E7: =ROUND(D9*IF(4<=6,Assumptions!B6,IF(4<=12,Assumptions!B7,IF(4<=24,Assumptions!B8,Assumptions!B9))),0) -> 2 | F7: =ROUND(E9*IF(5<=6,Assumptions!B6,IF(5<=12,Assumptions!B7,IF(5<=24,Assumptions!B8,Assumptions!B9))),0) -> 3 | G7: =ROUND(F9*IF(6<=6,Assumptions!B6,IF(6<=12,Assumptions!B7,IF(6<=24,Assumptions!B8,Assumptions!B9))),0) -> 3 | H7: =ROUND(G9*IF(7<=6,Assumptions!B6,IF(7<=12,Assumptions!B7,IF(7<=24,Assumptions!B8,Assumptions!B9))),0) -> 3 | I7: =ROUND(H9*IF(8<=6,Assumptions!B6,IF(8<=12,Assumptions!B7,IF(8<=24,Assumptions!B8,Assumptions!B9))),0) -> 4 | J7: =ROUND(I9*IF(9<=6,Assumptions!B6,IF(9<=12,Assumptions!B7,IF(9<=24,Assumptions!B8,Assumptions!B9))),0) -> 4 | K7: =ROUND(J9*IF(10<=6,Assumptions!B6,IF(10<=12,Assumptions!B7,IF(10<=24,Assumptions!B8,Assumptions!B9))),0) -> 5 | L7: =ROUND(K9*IF(11<=6,Assumptions!B6,IF(11<=12,Assumptions!B7,IF(11<=24,Assumptions!B8,Assumptions!B9))),0) -> 6 | M7: =ROUND(L9*IF(12<=6,Assumptions!B6,IF(12<=12,Assumptions!B7,IF(12<=24,Assumptions!B8,Assumptions!B9))),0) -> 7 | N7: =ROUND(M9*IF(13<=6,Assumptions!B6,IF(13<=12,Assumptions!B7,IF(13<=24,Assumptions!B8,Assumptions!B9))),0) -> 6 | O7: =ROUND(N9*IF(14<=6,Assumptions!B6,IF(14<=12,Assumptions!B7,IF(14<=24,Assumptions!B8,Assumptions!B9))),0) -> 7 | P7: =ROUND(O9*IF(15<=6,Assumptions!B6,IF(15<=12,Assumptions!B7,IF(15<=24,Assumptions!B8,Assumptions!B9))),0) -> 8 | Q7: =ROUND(P9*IF(16<=6,Assumptions!B6,IF(16<=12,Assumptions!B7,IF(16<=24,Assumptions!B8,Assumptions!B9))),0) -> 9 | R7: =ROUND(Q9*IF(17<=6,Assumptions!B6,IF(17<=12,Assumptions!B7,IF(17<=24,Assumptions!B8,Assumptions!B9))),0) -> 10 | S7: =ROUND(R9*IF(18<=6,Assumptions!B6,IF(18<=12,Assumptions!B7,IF(18<=24,Assumptions!B8,Assumptions!B9))),0) -> 11 | T7: =ROUND(S9*IF(19<=6,Assumptions!B6,IF(19<=12,Assumptions!B7,IF(19<=24,Assumptions!B8,Assumptions!B9))),0) -> 12 | U7: =ROUND(T9*IF(20<=6,Assumptions!B6,IF(20<=12,Assumptions!B7,IF(20<=24,Assumptions!B8,Assumptions!B9))),0) -> 14 | V7: =ROUND(U9*IF(21<=6,Assumptions!B6,IF(21<=12,Assumptions!B7,IF(21<=24,Assumptions!B8,Assumptions!B9))),0) -> 15 | W7: =ROUND(V9*IF(22<=6,Assumptions!B6,IF(22<=12,Assumptions!B7,IF(22<=24,Assumptions!B8,Assumptions!B9))),0) -> 17 | X7: =ROUND(W9*IF(23<=6,Assumptions!B6,IF(23<=12,Assumptions!B7,IF(23<=24,Assumptions!B8,Assumptions!B9))),0) -> 19 | Y7: =ROUND(X9*IF(24<=6,Assumptions!B6,IF(24<=12,Assumptions!B7,IF(24<=24,Assumptions!B8,Assumptions!B9))),0) -> 21 | Z7: =ROUND(Y9*IF(25<=6,Assumptions!B6,IF(25<=12,Assumptions!B7,IF(25<=24,Assumptions!B8,Assumptions!B9))),0) -> 16 | AA7: =ROUND(Z9*IF(26<=6,Assumptions!B6,IF(26<=12,Assumptions!B7,IF(26<=24,Assumptions!B8,Assumptions!B9))),0) -> 17 | AB7: =ROUND(AA9*IF(27<=6,Assumptions!B6,IF(27<=12,Assumptions!B7,IF(27<=24,Assumptions!B8,Assumptions!B9))),0) -> 18 | AC7: =ROUND(AB9*IF(28<=6,Assumptions!B6,IF(28<=12,Assumptions!B7,IF(28<=24,Assumptions!B8,Assumptions!B9))),0) -> 20 | AD7: =ROUND(AC9*IF(29<=6,Assumptions!B6,IF(29<=12,Assumptions!B7,IF(29<=24,Assumptions!B8,Assumptions!B9))),0) -> 21 | AE7: =ROUND(AD9*IF(30<=6,Assumptions!B6,IF(30<=12,Assumptions!B7,IF(30<=24,Assumptions!B8,Assumptions!B9))),0) -> 23 | AF7: =ROUND(AE9*IF(31<=6,Assumptions!B6,IF(31<=12,Assumptions!B7,IF(31<=24,Assumptions!B8,Assumptions!B9))),0) -> 24 | AG7: =ROUND(AF9*IF(32<=6,Assumptions!B6,IF(32<=12,Assumptions!B7,IF(32<=24,Assumptions!B8,Assumptions!B9))),0) -> 26 | AH7: =ROUND(AG9*IF(33<=6,Assumptions!B6,IF(33<=12,Assumptions!B7,IF(33<=24,Assumptions!B8,Assumptions!B9))),0) -> 28 | AI7: =ROUND(AH9*IF(34<=6,Assumptions!B6,IF(34<=12,Assumptions!B7,IF(34<=24,Assumptions!B8,Assumptions!B9))),0) -> 30 | AJ7: =ROUND(AI9*IF(35<=6,Assumptions!B6,IF(35<=12,Assumptions!B7,IF(35<=24,Assumptions!B8,Assumptions!B9))),0) -> 32 | AK7: =ROUND(AJ9*IF(36<=6,Assumptions!B6,IF(36<=12,Assumptions!B7,IF(36<=24,Assumptions!B8,Assumptions!B9))),0) -> 34
A8: Churned customers | B8: =0 -> 0 | C8: =ROUND(B9*Assumptions!B10,0) -> 0 | D8: =ROUND(C9*Assumptions!B10,0) -> 0 | E8: =ROUND(D9*Assumptions!B10,0) -> 0 | F8: =ROUND(E9*Assumptions!B10,0) -> 0 | G8: =ROUND(F9*Assumptions!B10,0) -> 0 | H8: =ROUND(G9*Assumptions!B10,0) -> 0 | I8: =ROUND(H9*Assumptions!B10,0) -> 1 | J8: =ROUND(I9*Assumptions!B10,0) -> 1 | K8: =ROUND(J9*Assumptions!B10,0) -> 1 | L8: =ROUND(K9*Assumptions!B10,0) -> 1 | M8: =ROUND(L9*Assumptions!B10,0) -> 1 | N8: =ROUND(M9*Assumptions!B10,0) -> 1 | O8: =ROUND(N9*Assumptions!B10,0) -> 1 | P8: =ROUND(O9*Assumptions!B10,0) -> 2 | Q8: =ROUND(P9*Assumptions!B10,0) -> 2 | R8: =ROUND(Q9*Assumptions!B10,0) -> 2 | S8: =ROUND(R9*Assumptions!B10,0) -> 2 | T8: =ROUND(S9*Assumptions!B10,0) -> 2 | U8: =ROUND(T9*Assumptions!B10,0) -> 3 | V8: =ROUND(U9*Assumptions!B10,0) -> 3 | W8: =ROUND(V9*Assumptions!B10,0) -> 3 | X8: =ROUND(W9*Assumptions!B10,0) -> 4 | Y8: =ROUND(X9*Assumptions!B10,0) -> 4 | Z8: =ROUND(Y9*Assumptions!B10,0) -> 5 | AA8: =ROUND(Z9*Assumptions!B10,0) -> 5 | AB8: =ROUND(AA9*Assumptions!B10,0) -> 5 | AC8: =ROUND(AB9*Assumptions!B10,0) -> 6 | AD8: =ROUND(AC9*Assumptions!B10,0) -> 6 | AE8: =ROUND(AD9*Assumptions!B10,0) -> 7 | AF8: =ROUND(AE9*Assumptions!B10,0) -> 7 | AG8: =ROUND(AF9*Assumptions!B10,0) -> 8 | AH8: =ROUND(AG9*Assumptions!B10,0) -> 8 | AI8: =ROUND(AH9*Assumptions!B10,0) -> 9 | AJ8: =ROUND(AI9*Assumptions!B10,0) -> 10 | AK8: =ROUND(AJ9*Assumptions!B10,0) -> 10
A9: Total customers | B9: =B7-B8 -> 5 | C9: =B9+C7-C8 -> 6 | D9: =C9+D7-D8 -> 8 | E9: =D9+E7-E8 -> 10 | F9: =E9+F7-F8 -> 13 | G9: =F9+G7-G8 -> 16 | H9: =G9+H7-H8 -> 19 | I9: =H9+I7-I8 -> 22 | J9: =I9+J7-J8 -> 25 | ... AK9: =AJ9+AK7-AK8 -> 363
A10: Agent service adopters | B10: =IF(1>=Assumptions!B20,ROUND(B9*Assumptions!B21,0),0) -> 0 | C10: =IF(2>=Assumptions!B20,ROUND(B9*MIN(Assumptions!B21+(2-Assumptions!B20)*Assumptions!B22,0.8),0),0) -> 0 | D10: =IF(3>=Assumptions!B20,ROUND(B9*MIN(Assumptions!B21+(3-Assumptions!B20)*Assumptions!B22,0.8),0),0) -> 0 | E10: =IF(4>=Assumptions!B20,ROUND(B9*MIN(Assumptions!B21+(4-Assumptions!B20)*Assumptions!B22,0.8),0),0) -> 0 | F10: =IF(5>=Assumptions!B20,ROUND(B9*MIN(Assumptions!B21+(5-Assumptions!B20)*Assumptions!B22,0.8),0),0) -> 0 | G10: =IF(6>=Assumptions!B20,ROUND(B9*MIN(Assumptions!B21+(6-Assumptions!B20)*Assumptions!B22,0.8),0),0) -> 0 | H10: =IF(7>=Assumptions!B20,ROUND(B9*MIN(Assumptions!B21+(7-Assumptions!B20)*Assumptions!B22,0.8),0),0) -> 0 | I10: =IF(8>=Assumptions!B20,ROUND(B9*MIN(Assumptions!B21+(8-Assumptions!B20)*Assumptions!B22,0.8),0),0) -> 0 | J10: =IF(9>=Assumptions!B20,ROUND(B9*MIN(Assumptions!B21+(9-Assumptions!B20)*Assumptions!B22,0.8),0),0) -> 0 | K10: =IF(10>=Assumptions!B20,ROUND(B9*MIN(Assumptions!B21+(10-Assumptions!B20)*Assumptions!B22,0.8),0),0) -> 1 | L10: =IF(11>=Assumptions!B20,ROUND(B9*MIN(Assumptions!B21+(11-Assumptions!B20)*Assumptions!B22,0.8),0),0) -> 1 | M10: =IF(12>=Assumptions!B20,ROUND(B9*MIN(Assumptions!B21+(12-Assumptions!B20)*Assumptions!B22,0.8),0),0) -> 1 | N10: =IF(13>=Assumptions!B20,ROUND(B9*MIN(Assumptions!B21+(13-Assumptions!B20)*Assumptions!B22,0.8),0),0) -> 2 | O10: =IF(14>=Assumptions!B20,ROUND(B9*MIN(Assumptions!B21+(14-Assumptions!B20)*Assumptions!B22,0.8),0),0) -> 2 | P10: =IF(15>=Assumptions!B20,ROUND(B9*MIN(Assumptions!B21+(15-Assumptions!B20)*Assumptions!B22,0.8),0),0) -> 2 | Q10: =IF(16>=Assumptions!B20,ROUND(B9*MIN(Assumptions!B21+(16-Assumptions!B20)*Assumptions!B22,0.8),0),0) -> 2 | R10: =IF(17>=Assumptions!B20,ROUND(B9*MIN(Assumptions!B21+(17-Assumptions!B20)*Assumptions!B22,0.8),0),0) -> 3 | S10: =IF(18>=Assumptions!B20,ROUND(B9*MIN(Assumptions!B21+(18-Assumptions!B20)*Assumptions!B22,0.8),0),0) -> 3 | T10: =IF(19>=Assumptions!B20,ROUND(B9*MIN(Assumptions!B21+(19-Assumptions!B20)*Assumptions!B22,0.8),0),0) -> 3 | U10: =IF(20>=Assumptions!B20,ROUND(B9*MIN(Assumptions!B21+(20-Assumptions!B20)*Assumptions!B22,0.8),0),0) -> 3 | V10: =IF(21>=Assumptions!B20,ROUND(B9*MIN(Assumptions!B21+(21-Assumptions!B20)*Assumptions!B22,0.8),0),0) -> 4 | W10: =IF(22>=Assumptions!B20,ROUND(B9*MIN(Assumptions!B21+(22-Assumptions!B20)*Assumptions!B22,0.8),0),0) -> 4 | X10: =IF(23>=Assumptions!B20,ROUND(B9*MIN(Assumptions!B21+(23-Assumptions!B20)*Assumptions!B22,0.8),0),0) -> 4 | Y10: =IF(24>=Assumptions!B20,ROUND(B9*MIN(Assumptions!B21+(24-Assumptions!B20)*Assumptions!B22,0.8),0),0) -> 4 | Z10: =IF(25>=Assumptions!B20,ROUND(B9*MIN(Assumptions!B21+(25-Assumptions!B20)*Assumptions!B22,0.8),0),0) -> 4 | AA10: =IF(26>=Assumptions!B20,ROUND(B9*MIN(Assumptions!B21+(26-Assumptions!B20)*Assumptions!B22,0.8),0),0) -> 4 | AB10: =IF(27>=Assumptions!B20,ROUND(B9*MIN(Assumptions!B21+(27-Assumptions!B20)*Assumptions!B22,0.8),0),0) -> 4 | AC10: =IF(28>=Assumptions!B20,ROUND(B9*MIN(Assumptions!B21+(28-Assumptions!B20)*Assumptions!B22,0.8),0),0) -> 4 | AD10: =IF(29>=Assumptions!B20,ROUND(B9*MIN(Assumptions!B21+(29-Assumptions!B20)*Assumptions!B22,0.8),0),0) -> 4 | AE10: =IF(30>=Assumptions!B20,ROUND(B9*MIN(Assumptions!B21+(30-Assumptions!B20)*Assumptions!B22,0.8),0),0) -> 4 | AF10: =IF(31>=Assumptions!B20,ROUND(B9*MIN(Assumptions!B21+(31-Assumptions!B20)*Assumptions!B22,0.8),0),0) -> 4 | AG10: =IF(32>=Assumptions!B20,ROUND(B9*MIN(Assumptions!B21+(32-Assumptions!B20)*Assumptions!B22,0.8),0),0) -> 4 | AH10: =IF(33>=Assumptions!B20,ROUND(B9*MIN(Assumptions!B21+(33-Assumptions!B20)*Assumptions!B22,0.8),0),0) -> 4 | AI10: =IF(34>=Assumptions!B20,ROUND(B9*MIN(Assumptions!B21+(34-Assumptions!B20)*Assumptions!B22,0.8),0),0) -> 4 | AJ10: =IF(35>=Assumptions!B20,ROUND(B9*MIN(Assumptions!B21+(35-Assumptions!B20)*Assumptions!B22,0.8),0),0) -> 4 | AK10: =IF(36>=Assumptions!B20,ROUND(B9*MIN(Assumptions!B21+(36-Assumptions!B20)*Assumptions!B22,0.8),0),0) -> 4
A12: REVENUE
A13: Avg API spend per customer (₦) | B13: =ROUND(Assumptions!B13*(1+Assumptions!B14)^(1-1),0) -> 150000 | C13: =ROUND(Assumptions!B13*(1+Assumptions!B14)^(2-1),0) -> 154500 | D13: =ROUND(Assumptions!B13*(1+Assumptions!B14)^(3-1),0) -> 159135 | E13: =ROUND(Assumptions!B13*(1+Assumptions!B14)^(4-1),0) -> 163909 | F13: =ROUND(Assumptions!B13*(1+Assumptions!B14)^(5-1),0) -> 168826 | G13: =ROUND(Assumptions!B13*(1+Assumptions!B14)^(6-1),0) -> 173891 | H13: =ROUND(Assumptions!B13*(1+Assumptions!B14)^(7-1),0) -> 179108 | I13: =ROUND(Assumptions!B13*(1+Assumptions!B14)^(8-1),0) -> 184481 | J13: =ROUND(Assumptions!B13*(1+Assumptions!B14)^(9-1),0) -> 190016 | K13: =ROUND(Assumptions!B13*(1+Assumptions!B14)^(10-1),0) -> 195716 | L13: =ROUND(Assumptions!B13*(1+Assumptions!B14)^(11-1),0) -> 201587 | M13: =ROUND(Assumptions!B13*(1+Assumptions!B14)^(12-1),0) -> 207635 | N13: =ROUND(Assumptions!B13*(1+Assumptions!B14)^(13-1),0) -> 213864 | O13: =ROUND(Assumptions!B13*(1+Assumptions!B14)^(14-1),0) -> 220280 | P13: =ROUND(Assumptions!B13*(1+Assumptions!B14)^(15-1),0) -> 226888 | Q13: =ROUND(Assumptions!B13*(1+Assumptions!B14)^(16-1),0) -> 233695 | R13: =ROUND(Assumptions!B13*(1+Assumptions!B14)^(17-1),0) -> 240706 | S13: =ROUND(Assumptions!B13*(1+Assumptions!B14)^(18-1),0) -> 247927 | T13: =ROUND(Assumptions!B13*(1+Assumptions!B14)^(19-1),0) -> 255365 | U13: =ROUND(Assumptions!B13*(1+Assumptions!B14)^(20-1),0) -> 263026 | V13: =ROUND(Assumptions!B13*(1+Assumptions!B14)^(21-1),0) -> 270917 | W13: =ROUND(Assumptions!B13*(1+Assumptions!B14)^(22-1),0) -> 279044 | X13: =ROUND(Assumptions!B13*(1+Assumptions!B14)^(23-1),0) -> 287416 | Y13: =ROUND(Assumptions!B13*(1+Assumptions!B14)^(24-1),0) -> 296038 | Z13: =ROUND(Assumptions!B13*(1+Assumptions!B14)^(25-1),0) -> 304919 | AA13: =ROUND(Assumptions!B13*(1+Assumptions!B14)^(26-1),0) -> 314067 | AB13: =ROUND(Assumptions!B13*(1+Assumptions!B14)^(27-1),0) -> 323489 | AC13: =ROUND(Assumptions!B13*(1+Assumptions!B14)^(28-1),0) -> 333193 | AD13: =ROUND(Assumptions!B13*(1+Assumptions!B14)^(29-1),0) -> 343189 | AE13: =ROUND(Assumptions!B13*(1+Assumptions!B14)^(30-1),0) -> 353485 | AF13: =ROUND(Assumptions!B13*(1+Assumptions!B14)^(31-1),0) -> 364089 | AG13: =ROUND(Assumptions!B13*(1+Assumptions!B14)^(32-1),0) -> 375012 | AH13: =ROUND(Assumptions!B13*(1+Assumptions!B14)^(33-1),0) -> 386262 | AI13: =ROUND(Assumptions!B13*(1+Assumptions!B14)^(34-1),0) -> 397850 | AJ13: =ROUND(Assumptions!B13*(1+Assumptions!B14)^(35-1),0) -> 409786 | AK13: =ROUND(Assumptions!B13*(1+Assumptions!B14)^(36-1),0) -> 422079
A14: Gross API passthrough | B14: =B9*B13 -> 750000 | C14: =C9*C13 -> 927000 | D14: =D9*D13 -> 1273080 | E14: =E9*E13 -> 1639090 | F14: =F9*F13 -> 2194738 | G14: =G9*G13 -> 2782256 | H14: =H9*H13 -> 3403052 | I14: =I9*I13 -> 4058582 | ... AK14: =AK9*AK13 -> 153214677
A15: Take rate revenue | B15: =B14*Assumptions!B15 -> 60000 | C15: =C14*Assumptions!B15 -> 74160 | D15: =D14*Assumptions!B15 -> 101846.4 | E15: =E14*Assumptions!B15 -> 131127.2 | F15: =F14*Assumptions!B15 -> 175579.04 | G15: =G14*Assumptions!B15 -> 222580.48 | H15: =H14*Assumptions!B15 -> 272244.16 | I15: =I14*Assumptions!B15 -> 324686.56 | J15: =J14*Assumptions!B15 -> 380032 | K15: =K14*Assumptions!B15 -> 454061.12 | L15: =L14*Assumptions!B15 -> 548316.64 | M15: =M14*Assumptions!B15 -> 664432 | N15: =N14*Assumptions!B15 -> 769910.4 | O15: =O14*Assumptions!B15 -> 898742.4 | P15: =P14*Assumptions!B15 -> 1034609.3 | Q15: =Q14*Assumptions!B15 -> 1196518.4 | R15: =R14*Assumptions!B15 -> 1386466.6 | S15: =S14*Assumptions!B15 -> 1606567 | T15: =T14*Assumptions!B15 -> 1859057.2 | U15: =U14*Assumptions!B15 -> 2146292.2 | V15: =V14*Assumptions!B15 -> 2470763 | W15: =W14*Assumptions!B15 -> 2857410.6 | X15: =X14*Assumptions!B15 -> 3288039 | Y15: =Y14*Assumptions!B15 -> 3789286.4 | Z15: =Z14*Assumptions!B15 -> 4171291.9 | AA15: =AA14*Assumptions!B15 -> 4597940.9 | AB15: =AB14*Assumptions!B15 -> 5072307.5 | AC15: =AC14*Assumptions!B15 -> 5597642.4 | AD15: =AD14*Assumptions!B15 -> 6177402 | AE15: =AE14*Assumptions!B15 -> 6815190.8 | AF15: =AF14*Assumptions!B15 -> 7514797 | AG15: =AG14*Assumptions!B15 -> 8280265 | AH15: =AH14*Assumptions!B15 -> 9146684.2 | AI15: =AI14*Assumptions!B15 -> 10089476 | AJ15: =AJ14*Assumptions!B15 -> 11113396 | AK15: =AK14*Assumptions!B15 -> 12257174
A16: Routing savings generated | B16: =B14*Assumptions!B17 -> 112500 | C16: =C14*Assumptions!B17 -> 139050 | D16: =D14*Assumptions!B17 -> 190962 | E16: =E14*Assumptions!B17 -> 245863.5 | F16: =F14*Assumptions!B17 -> 329210.7 | G16: =G14*Assumptions!B17 -> 417338.4 | H16: =H14*Assumptions!B17 -> 510457.8 | I16: =I14*Assumptions!B17 -> 608787.3 | J16: =J14*Assumptions!B17 -> 712560 | K16: =K14*Assumptions!B17 -> 851364.6 | L16: =L14*Assumptions!B17 -> 1028093.7 | M16: =M14*Assumptions!B17 -> 1245810 | N16: =N14*Assumptions!B17 -> 1443582 | O16: =O14*Assumptions!B17 -> 1685142 | P16: =P14*Assumptions!B17 -> 1939892.4 | Q16: =Q14*Assumptions!B17 -> 2243472 | R16: =R14*Assumptions!B17 -> 2599624.8 | S16: =S14*Assumptions!B17 -> 3012313 | T16: =T14*Assumptions!B17 -> 3485732.2 | U16: =U14*Assumptions!B17 -> 4024297.8 | V16: =V14*Assumptions!B17 -> 4632680.7 | W16: =W14*Assumptions!B17 -> 5357644.8 | X16: =X14*Assumptions!B17 -> 6165073.2 | Y16: =Y14*Assumptions!B17 -> 7104912 | Z16: =Z14*Assumptions!B17 -> 7821172.3 | AA16: =AA14*Assumptions!B17 -> 8621139.2 | AB16: =AB14*Assumptions!B17 -> 9510576.6 | AC16: =AC14*Assumptions!B17 -> 10495580 | AD16: =AD14*Assumptions!B17 -> 11582629 | AE16: =AE14*Assumptions!B17 -> 12778483 | AF16: =AF14*Assumptions!B17 -> 14090244 | AG16: =AG14*Assumptions!B17 -> 15525497 | AH16: =AH14*Assumptions!B17 -> 17150033 | AI16: =AI14*Assumptions!B17 -> 18917768 | AJ16: =AJ14*Assumptions!B17 -> 20837618 | AK16: =AK14*Assumptions!B17 -> 22982202
A17: Routing savings share revenue | B17: =B16*Assumptions!B16 -> 22500 | C17: =C16*Assumptions!B16 -> 27810 | D17: =D16*Assumptions!B16 -> 38192.4 | E17: =E16*Assumptions!B16 -> 49172.7 | F17: =F16*Assumptions!B16 -> 65842.14 | G17: =G16*Assumptions!B16 -> 83467.68 | H17: =H16*Assumptions!B16 -> 102091.56 | I17: =I16*Assumptions!B16 -> 121757.46 | J17: =J16*Assumptions!B16 -> 142512 | K17: =K16*Assumptions!B16 -> 170272.92 | L17: =L16*Assumptions!B16 -> 205618.74 | M17: =M16*Assumptions!B16 -> 249162 | N17: =N16*Assumptions!B16 -> 288716.4 | O17: =O16*Assumptions!B16 -> 337028.4 | P17: =P16*Assumptions!B16 -> 387978.48 | Q17: =Q16*Assumptions!B16 -> 448694.4 | R17: =R16*Assumptions!B16 -> 519924.96 | S17: =S16*Assumptions!B16 -> 602462.61 | T17: =T16*Assumptions!B16 -> 697146.45 | U17: =U16*Assumptions!B16 -> 804859.56 | V17: =V16*Assumptions!B16 -> 926536.14 | W17: =W16*Assumptions!B16 -> 1071529 | X17: =X16*Assumptions!B16 -> 1233014.6 | Y17: =Y16*Assumptions!B16 -> 1420982.4 | Z17: =Z16*Assumptions!B16 -> 1564234.5 | AA17: =AA16*Assumptions!B16 -> 1724227.8 | AB17: =AB16*Assumptions!B16 -> 1902115.3 | AC17: =AC16*Assumptions!B16 -> 2099115.9 | AD17: =AD16*Assumptions!B16 -> 2316525.8 | AE17: =AE16*Assumptions!B16 -> 2555696.5 | AF17: =AF16*Assumptions!B16 -> 2818048.9 | AG17: =AG16*Assumptions!B16 -> 3105099.4 | AH17: =AH16*Assumptions!B16 -> 3430006.6 | AI17: =AI16*Assumptions!B16 -> 3783553.5 | AJ17: =AJ16*Assumptions!B16 -> 4167523.6 | AK17: =AK16*Assumptions!B16 -> 4596440.3
A18: Agent service passthrough | B18: =IF(1>=Assumptions!B20,B10*Assumptions!B23*(1+Assumptions!B24)^(MAX(1-Assumptions!B20,0)),0) -> 0 | C18: =IF(2>=Assumptions!B20,C10*Assumptions!B23*(1+Assumptions!B24)^(MAX(2-Assumptions!B20,0)),0) -> 0 | D18: =IF(3>=Assumptions!B20,D10*Assumptions!B23*(1+Assumptions!B24)^(MAX(3-Assumptions!B20,0)),0) -> 0 | E18: =IF(4>=Assumptions!B20,E10*Assumptions!B23*(1+Assumptions!B24)^(MAX(4-Assumptions!B20,0)),0) -> 0 | F18: =IF(5>=Assumptions!B20,F10*Assumptions!B23*(1+Assumptions!B24)^(MAX(5-Assumptions!B20,0)),0) -> 0 | G18: =IF(6>=Assumptions!B20,G10*Assumptions!B23*(1+Assumptions!B24)^(MAX(6-Assumptions!B20,0)),0) -> 0 | H18: =IF(7>=Assumptions!B20,H10*Assumptions!B23*(1+Assumptions!B24)^(MAX(7-Assumptions!B20,0)),0) -> 0 | I18: =IF(8>=Assumptions!B20,I10*Assumptions!B23*(1+Assumptions!B24)^(MAX(8-Assumptions!B20,0)),0) -> 0 | J18: =IF(9>=Assumptions!B20,J10*Assumptions!B23*(1+Assumptions!B24)^(MAX(9-Assumptions!B20,0)),0) -> 0 | K18: =IF(10>=Assumptions!B20,K10*Assumptions!B23*(1+Assumptions!B24)^(MAX(10-Assumptions!B20,0)),0) -> 50000 | L18: =IF(11>=Assumptions!B20,L10*Assumptions!B23*(1+Assumptions!B24)^(MAX(11-Assumptions!B20,0)),0) -> 52500 | M18: =IF(12>=Assumptions!B20,M10*Assumptions!B23*(1+Assumptions!B24)^(MAX(12-Assumptions!B20,0)),0) -> 55125 | N18: =IF(13>=Assumptions!B20,N10*Assumptions!B23*(1+Assumptions!B24)^(MAX(13-Assumptions!B20,0)),0) -> 115762.5 | O18: =IF(14>=Assumptions!B20,O10*Assumptions!B23*(1+Assumptions!B24)^(MAX(14-Assumptions!B20,0)),0) -> 121550.62 | P18: =IF(15>=Assumptions!B20,P10*Assumptions!B23*(1+Assumptions!B24)^(MAX(15-Assumptions!B20,0)),0) -> 127628.16 | Q18: =IF(16>=Assumptions!B20,Q10*Assumptions!B23*(1+Assumptions!B24)^(MAX(16-Assumptions!B20,0)),0) -> 134009.56 | R18: =IF(17>=Assumptions!B20,R10*Assumptions!B23*(1+Assumptions!B24)^(MAX(17-Assumptions!B20,0)),0) -> 211065.06 | S18: =IF(18>=Assumptions!B20,S10*Assumptions!B23*(1+Assumptions!B24)^(MAX(18-Assumptions!B20,0)),0) -> 221618.32 | T18: =IF(19>=Assumptions!B20,T10*Assumptions!B23*(1+Assumptions!B24)^(MAX(19-Assumptions!B20,0)),0) -> 232699.23 | U18: =IF(20>=Assumptions!B20,U10*Assumptions!B23*(1+Assumptions!B24)^(MAX(20-Assumptions!B20,0)),0) -> 244334.19 | V18: =IF(21>=Assumptions!B20,V10*Assumptions!B23*(1+Assumptions!B24)^(MAX(21-Assumptions!B20,0)),0) -> 342067.87 | W18: =IF(22>=Assumptions!B20,W10*Assumptions!B23*(1+Assumptions!B24)^(MAX(22-Assumptions!B20,0)),0) -> 359171.27 | X18: =IF(23>=Assumptions!B20,X10*Assumptions!B23*(1+Assumptions!B24)^(MAX(23-Assumptions!B20,0)),0) -> 377129.83 | Y18: =IF(24>=Assumptions!B20,Y10*Assumptions!B23*(1+Assumptions!B24)^(MAX(24-Assumptions!B20,0)),0) -> 395986.32 | Z18: =IF(25>=Assumptions!B20,Z10*Assumptions!B23*(1+Assumptions!B24)^(MAX(25-Assumptions!B20,0)),0) -> 415785.64 | AA18: =IF(26>=Assumptions!B20,AA10*Assumptions!B23*(1+Assumptions!B24)^(MAX(26-Assumptions!B20,0)),0) -> 436574.92 | AB18: =IF(27>=Assumptions!B20,AB10*Assumptions!B23*(1+Assumptions!B24)^(MAX(27-Assumptions!B20,0)),0) -> 458403.66 | AC18: =IF(28>=Assumptions!B20,AC10*Assumptions!B23*(1+Assumptions!B24)^(MAX(28-Assumptions!B20,0)),0) -> 481323.85 | AD18: =IF(29>=Assumptions!B20,AD10*Assumptions!B23*(1+Assumptions!B24)^(MAX(29-Assumptions!B20,0)),0) -> 505390.04 | AE18: =IF(30>=Assumptions!B20,AE10*Assumptions!B23*(1+Assumptions!B24)^(MAX(30-Assumptions!B20,0)),0) -> 530659.54 | AF18: =IF(31>=Assumptions!B20,AF10*Assumptions!B23*(1+Assumptions!B24)^(MAX(31-Assumptions!B20,0)),0) -> 557192.52 | AG18: =IF(32>=Assumptions!B20,AG10*Assumptions!B23*(1+Assumptions!B24)^(MAX(32-Assumptions!B20,0)),0) -> 585052.14 | AH18: =IF(33>=Assumptions!B20,AH10*Assumptions!B23*(1+Assumptions!B24)^(MAX(33-Assumptions!B20,0)),0) -> 614304.75 | AI18: =IF(34>=Assumptions!B20,AI10*Assumptions!B23*(1+Assumptions!B24)^(MAX(34-Assumptions!B20,0)),0) -> 645019.99 | AJ18: =IF(35>=Assumptions!B20,AJ10*Assumptions!B23*(1+Assumptions!B24)^(MAX(35-Assumptions!B20,0)),0) -> 677270.99 | AK18: =IF(36>=Assumptions!B20,AK10*Assumptions!B23*(1+Assumptions!B24)^(MAX(36-Assumptions!B20,0)),0) -> 711134.54
A19: Agent service take rate revenue | B19: =B18*Assumptions!B25 -> 0 | C19: =C18*Assumptions!B25 -> 0 | D19: =D18*Assumptions!B25 -> 0 | E19: =E18*Assumptions!B25 -> 0 | F19: =F18*Assumptions!B25 -> 0 | G19: =G18*Assumptions!B25 -> 0 | H19: =H18*Assumptions!B25 -> 0 | I19: =I18*Assumptions!B25 -> 0 | J19: =J18*Assumptions!B25 -> 0 | K19: =K18*Assumptions!B25 -> 2500 | L19: =L18*Assumptions!B25 -> 2625 | M19: =M18*Assumptions!B25 -> 2756.25 | N19: =N18*Assumptions!B25 -> 5788.125 | O19: =O18*Assumptions!B25 -> 6077.5312 | P19: =P18*Assumptions!B25 -> 6381.4078 | Q19: =Q18*Assumptions!B25 -> 6700.4782 | R19: =R18*Assumptions!B25 -> 10553.253 | S19: =S18*Assumptions!B25 -> 11080.916 | T19: =T18*Assumptions!B25 -> 11634.962 | U19: =U18*Assumptions!B25 -> 12216.71 | V19: =V18*Assumptions!B25 -> 17103.394 | W19: =W18*Assumptions!B25 -> 17958.563 | X19: =X18*Assumptions!B25 -> 18856.491 | Y19: =Y18*Assumptions!B25 -> 19799.316 | Z19: =Z18*Assumptions!B25 -> 20789.282 | AA19: =AA18*Assumptions!B25 -> 21828.746 | AB19: =AB18*Assumptions!B25 -> 22920.183 | AC19: =AC18*Assumptions!B25 -> 24066.192 | AD19: =AD18*Assumptions!B25 -> 25269.502 | AE19: =AE18*Assumptions!B25 -> 26532.977 | AF19: =AF18*Assumptions!B25 -> 27859.626 | AG19: =AG18*Assumptions!B25 -> 29252.607 | AH19: =AH18*Assumptions!B25 -> 30715.238 | AI19: =AI18*Assumptions!B25 -> 32250.999 | AJ19: =AJ18*Assumptions!B25 -> 33863.549 | AK19: =AK18*Assumptions!B25 -> 35556.727
A20: USDT FX spread revenue | B20: =IF(1>=Assumptions!B28,(B14+B18)*Assumptions!B29*Assumptions!B30,0) -> 0 | C20: =IF(2>=Assumptions!B28,(C14+C18)*Assumptions!B29*Assumptions!B30,0) -> 0 | D20: =IF(3>=Assumptions!B28,(D14+D18)*Assumptions!B29*Assumptions!B30,0) -> 0 | E20: =IF(4>=Assumptions!B28,(E14+E18)*Assumptions!B29*Assumptions!B30,0) -> 0 | F20: =IF(5>=Assumptions!B28,(F14+F18)*Assumptions!B29*Assumptions!B30,0) -> 0 | G20: =IF(6>=Assumptions!B28,(G14+G18)*Assumptions!B29*Assumptions!B30,0) -> 0 | H20: =IF(7>=Assumptions!B28,(H14+H18)*Assumptions!B29*Assumptions!B30,0) -> 0 | I20: =IF(8>=Assumptions!B28,(I14+I18)*Assumptions!B29*Assumptions!B30,0) -> 0 | J20: =IF(9>=Assumptions!B28,(J14+J18)*Assumptions!B29*Assumptions!B30,0) -> 0 | K20: =IF(10>=Assumptions!B28,(K14+K18)*Assumptions!B29*Assumptions!B30,0) -> 8588.646 | L20: =IF(11>=Assumptions!B28,(L14+L18)*Assumptions!B29*Assumptions!B30,0) -> 10359.687 | M20: =IF(12>=Assumptions!B28,(M14+M18)*Assumptions!B29*Assumptions!B30,0) -> 12540.788 | N20: =IF(13>=Assumptions!B28,(N14+N18)*Assumptions!B29*Assumptions!B30,0) -> 14609.464 | O20: =IF(14>=Assumptions!B28,(O14+O18)*Assumptions!B29*Assumptions!B30,0) -> 17033.746 | P20: =IF(15>=Assumptions!B28,(P14+P18)*Assumptions!B29*Assumptions!B30,0) -> 19590.366 | Q20: =IF(16>=Assumptions!B28,(Q14+Q18)*Assumptions!B29*Assumptions!B30,0) -> 22635.734 | R20: =IF(17>=Assumptions!B28,(R14+R18)*Assumptions!B29*Assumptions!B30,0) -> 26312.846 | S20: =IF(18>=Assumptions!B28,(S14+S18)*Assumptions!B29*Assumptions!B30,0) -> 30455.558 | T20: =IF(19>=Assumptions!B28,(T14+T18)*Assumptions!B29*Assumptions!B30,0) -> 35206.371 | U20: =IF(20>=Assumptions!B28,(U14+U18)*Assumptions!B29*Assumptions!B30,0) -> 40609.479 | V20: =IF(21>=Assumptions!B28,(V14+V18)*Assumptions!B29*Assumptions!B30,0) -> 46839.909 | W20: =IF(22>=Assumptions!B28,(W14+W18)*Assumptions!B29*Assumptions!B30,0) -> 54115.205 | X20: =IF(23>=Assumptions!B28,(X14+X18)*Assumptions!B29*Assumptions!B30,0) -> 62216.427 | Y20: =IF(24>=Assumptions!B28,(Y14+Y18)*Assumptions!B29*Assumptions!B30,0) -> 71643.099 | Z20: =IF(25>=Assumptions!B28,(Z14+Z18)*Assumptions!B29*Assumptions!B30,0) -> 78835.402 | AA20: =IF(26>=Assumptions!B28,(AA14+AA18)*Assumptions!B29*Assumptions!B30,0) -> 86866.254 | AB20: =IF(27>=Assumptions!B28,(AB14+AB18)*Assumptions!B29*Assumptions!B30,0) -> 95793.371 | AC20: =IF(28>=Assumptions!B28,(AC14+AC18)*Assumptions!B29*Assumptions!B30,0) -> 105677.78 | AD20: =IF(29>=Assumptions!B28,(AD14+AD18)*Assumptions!B29*Assumptions!B30,0) -> 116584.37 | AE20: =IF(30>=Assumptions!B28,(AE14+AE18)*Assumptions!B29*Assumptions!B30,0) -> 128580.82 | AF20: =IF(31>=Assumptions!B28,(AF14+AF18)*Assumptions!B29*Assumptions!B30,0) -> 141738.23 | AG20: =IF(32>=Assumptions!B28,(AG14+AG18)*Assumptions!B29*Assumptions!B30,0) -> 156132.55 | AH20: =IF(33>=Assumptions!B28,(AH14+AH18)*Assumptions!B29*Assumptions!B30,0) -> 172421.79 | AI20: =IF(34>=Assumptions!B28,(AI14+AI18)*Assumptions!B29*Assumptions!B30,0) -> 190145.2 | AJ20: =IF(35>=Assumptions!B28,(AJ14+AJ18)*Assumptions!B29*Assumptions!B30,0) -> 209392.09 | AK20: =IF(36>=Assumptions!B28,(AK14+AK18)*Assumptions!B29*Assumptions!B30,0) -> 230888.72
A21: Total Revenue | B21: =B15+B17+B19+B20 -> 82500 | C21: =C15+C17+C19+C20 -> 101970 | D21: =D15+D17+D19+D20 -> 140038.8 | E21: =E15+E17+E19+E20 -> 180299.9 | F21: =F15+F17+F19+F20 -> 241421.18 | G21: =G15+G17+G19+G20 -> 306048.16 | H21: =H15+H17+H19+H20 -> 374335.72 | I21: =I15+I17+I19+I20 -> 446444.02 | ... AK21: =AK15+AK17+AK19+AK20 -> 17120060
A23: COSTS
A24: Cloud infrastructure | B24: =Assumptions!B33*(1+Assumptions!B34)^(1-1) -> 800000 | C24: =Assumptions!B33*(1+Assumptions!B34)^(2-1) -> 864000 | D24: =Assumptions!B33*(1+Assumptions!B34)^(3-1) -> 933120 | E24: =Assumptions!B33*(1+Assumptions!B34)^(4-1) -> 1007769.6 | F24: =Assumptions!B33*(1+Assumptions!B34)^(5-1) -> 1088391.2 | G24: =Assumptions!B33*(1+Assumptions!B34)^(6-1) -> 1175462.5 | H24: =Assumptions!B33*(1+Assumptions!B34)^(7-1) -> 1269499.5 | I24: =Assumptions!B33*(1+Assumptions!B34)^(8-1) -> 1371059.4 | J24: =Assumptions!B33*(1+Assumptions!B34)^(9-1) -> 1480744.2 | K24: =Assumptions!B33*(1+Assumptions!B34)^(10-1) -> 1599203.7 | L24: =Assumptions!B33*(1+Assumptions!B34)^(11-1) -> 1727140 | M24: =Assumptions!B33*(1+Assumptions!B34)^(12-1) -> 1865311.2 | N24: =Assumptions!B33*(1+Assumptions!B34)^(13-1) -> 2014536.1 | O24: =Assumptions!B33*(1+Assumptions!B34)^(14-1) -> 2175699 | P24: =Assumptions!B33*(1+Assumptions!B34)^(15-1) -> 2349754.9 | Q24: =Assumptions!B33*(1+Assumptions!B34)^(16-1) -> 2537735.3 | R24: =Assumptions!B33*(1+Assumptions!B34)^(17-1) -> 2740754.1 | S24: =Assumptions!B33*(1+Assumptions!B34)^(18-1) -> 2960014.4 | T24: =Assumptions!B33*(1+Assumptions!B34)^(19-1) -> 3196815.6 | U24: =Assumptions!B33*(1+Assumptions!B34)^(20-1) -> 3452560.8 | V24: =Assumptions!B33*(1+Assumptions!B34)^(21-1) -> 3728765.7 | W24: =Assumptions!B33*(1+Assumptions!B34)^(22-1) -> 4027067 | X24: =Assumptions!B33*(1+Assumptions!B34)^(23-1) -> 4349232.3 | Y24: =Assumptions!B33*(1+Assumptions!B34)^(24-1) -> 4697170.9 | Z24: =Assumptions!B33*(1+Assumptions!B34)^(25-1) -> 5072944.6 | AA24: =Assumptions!B33*(1+Assumptions!B34)^(26-1) -> 5478780.2 | AB24: =Assumptions!B33*(1+Assumptions!B34)^(27-1) -> 5917082.6 | AC24: =Assumptions!B33*(1+Assumptions!B34)^(28-1) -> 6390449.2 | AD24: =Assumptions!B33*(1+Assumptions!B34)^(29-1) -> 6901685.1 | AE24: =Assumptions!B33*(1+Assumptions!B34)^(30-1) -> 7453819.9 | AF24: =Assumptions!B33*(1+Assumptions!B34)^(31-1) -> 8050125.5 | AG24: =Assumptions!B33*(1+Assumptions!B34)^(32-1) -> 8694135.6 | AH24: =Assumptions!B33*(1+Assumptions!B34)^(33-1) -> 9389666.4 | AI24: =Assumptions!B33*(1+Assumptions!B34)^(34-1) -> 10140840 | AJ24: =Assumptions!B33*(1+Assumptions!B34)^(35-1) -> 10952107 | AK24: =Assumptions!B33*(1+Assumptions!B34)^(36-1) -> 11828275
A25: Team (salaries) | B25: =(Assumptions!B35+INT((1-1)/Assumptions!B37))*Assumptions!B36 -> 3600000 | C25: =(Assumptions!B35+INT((2-1)/Assumptions!B37))*Assumptions!B36 -> 3600000 | D25: =(Assumptions!B35+INT((3-1)/Assumptions!B37))*Assumptions!B36 -> 3600000 | E25: =(Assumptions!B35+INT((4-1)/Assumptions!B37))*Assumptions!B36 -> 3600000 | F25: =(Assumptions!B35+INT((5-1)/Assumptions!B37))*Assumptions!B36 -> 4800000 | G25: =(Assumptions!B35+INT((6-1)/Assumptions!B37))*Assumptions!B36 -> 4800000 | H25: =(Assumptions!B35+INT((7-1)/Assumptions!B37))*Assumptions!B36 -> 4800000 | I25: =(Assumptions!B35+INT((8-1)/Assumptions!B37))*Assumptions!B36 -> 4800000 | J25: =(Assumptions!B35+INT((9-1)/Assumptions!B37))*Assumptions!B36 -> 6000000 | K25: =(Assumptions!B35+INT((10-1)/Assumptions!B37))*Assumptions!B36 -> 6000000 | L25: =(Assumptions!B35+INT((11-1)/Assumptions!B37))*Assumptions!B36 -> 6000000 | M25: =(Assumptions!B35+INT((12-1)/Assumptions!B37))*Assumptions!B36 -> 6000000 | N25: =(Assumptions!B35+INT((13-1)/Assumptions!B37))*Assumptions!B36 -> 7200000 | O25: =(Assumptions!B35+INT((14-1)/Assumptions!B37))*Assumptions!B36 -> 7200000 | P25: =(Assumptions!B35+INT((15-1)/Assumptions!B37))*Assumptions!B36 -> 7200000 | Q25: =(Assumptions!B35+INT((16-1)/Assumptions!B37))*Assumptions!B36 -> 7200000 | R25: =(Assumptions!B35+INT((17-1)/Assumptions!B37))*Assumptions!B36 -> 8400000 | S25: =(Assumptions!B35+INT((18-1)/Assumptions!B37))*Assumptions!B36 -> 8400000 | T25: =(Assumptions!B35+INT((19-1)/Assumptions!B37))*Assumptions!B36 -> 8400000 | U25: =(Assumptions!B35+INT((20-1)/Assumptions!B37))*Assumptions!B36 -> 8400000 | V25: =(Assumptions!B35+INT((21-1)/Assumptions!B37))*Assumptions!B36 -> 9600000 | W25: =(Assumptions!B35+INT((22-1)/Assumptions!B37))*Assumptions!B36 -> 9600000 | X25: =(Assumptions!B35+INT((23-1)/Assumptions!B37))*Assumptions!B36 -> 9600000 | Y25: =(Assumptions!B35+INT((24-1)/Assumptions!B37))*Assumptions!B36 -> 9600000 | Z25: =(Assumptions!B35+INT((25-1)/Assumptions!B37))*Assumptions!B36 -> 10800000 | AA25: =(Assumptions!B35+INT((26-1)/Assumptions!B37))*Assumptions!B36 -> 10800000 | AB25: =(Assumptions!B35+INT((27-1)/Assumptions!B37))*Assumptions!B36 -> 10800000 | AC25: =(Assumptions!B35+INT((28-1)/Assumptions!B37))*Assumptions!B36 -> 10800000 | AD25: =(Assumptions!B35+INT((29-1)/Assumptions!B37))*Assumptions!B36 -> 12000000 | AE25: =(Assumptions!B35+INT((30-1)/Assumptions!B37))*Assumptions!B36 -> 12000000 | AF25: =(Assumptions!B35+INT((31-1)/Assumptions!B37))*Assumptions!B36 -> 12000000 | AG25: =(Assumptions!B35+INT((32-1)/Assumptions!B37))*Assumptions!B36 -> 12000000 | AH25: =(Assumptions!B35+INT((33-1)/Assumptions!B37))*Assumptions!B36 -> 13200000 | AI25: =(Assumptions!B35+INT((34-1)/Assumptions!B37))*Assumptions!B36 -> 13200000 | AJ25: =(Assumptions!B35+INT((35-1)/Assumptions!B37))*Assumptions!B36 -> 13200000 | AK25: =(Assumptions!B35+INT((36-1)/Assumptions!B37))*Assumptions!B36 -> 13200000
A26: Marketing | B26: =Assumptions!B38*(1+Assumptions!B39)^(1-1) -> 200000 | C26: =Assumptions!B38*(1+Assumptions!B39)^(2-1) -> 220000 | D26: =Assumptions!B38*(1+Assumptions!B39)^(3-1) -> 242000 | E26: =Assumptions!B38*(1+Assumptions!B39)^(4-1) -> 266200 | F26: =Assumptions!B38*(1+Assumptions!B39)^(5-1) -> 292820 | G26: =Assumptions!B38*(1+Assumptions!B39)^(6-1) -> 322102 | H26: =Assumptions!B38*(1+Assumptions!B39)^(7-1) -> 354312.2 | I26: =Assumptions!B38*(1+Assumptions!B39)^(8-1) -> 389743.42 | J26: =Assumptions!B38*(1+Assumptions!B39)^(9-1) -> 428717.76 | K26: =Assumptions!B38*(1+Assumptions!B39)^(10-1) -> 471589.54 | L26: =Assumptions!B38*(1+Assumptions!B39)^(11-1) -> 518748.49 | M26: =Assumptions!B38*(1+Assumptions!B39)^(12-1) -> 570623.34 | N26: =Assumptions!B38*(1+Assumptions!B39)^(13-1) -> 627685.68 | O26: =Assumptions!B38*(1+Assumptions!B39)^(14-1) -> 690454.24 | P26: =Assumptions!B38*(1+Assumptions!B39)^(15-1) -> 759499.67 | Q26: =Assumptions!B38*(1+Assumptions!B39)^(16-1) -> 835449.63 | R26: =Assumptions!B38*(1+Assumptions!B39)^(17-1) -> 918994.6 | S26: =Assumptions!B38*(1+Assumptions!B39)^(18-1) -> 1010894.1 | T26: =Assumptions!B38*(1+Assumptions!B39)^(19-1) -> 1111983.5 | U26: =Assumptions!B38*(1+Assumptions!B39)^(20-1) -> 1223181.8 | V26: =Assumptions!B38*(1+Assumptions!B39)^(21-1) -> 1345500 | W26: =Assumptions!B38*(1+Assumptions!B39)^(22-1) -> 1480050 | X26: =Assumptions!B38*(1+Assumptions!B39)^(23-1) -> 1628055 | Y26: =Assumptions!B38*(1+Assumptions!B39)^(24-1) -> 1790860.5 | Z26: =Assumptions!B38*(1+Assumptions!B39)^(25-1) -> 1969946.5 | AA26: =Assumptions!B38*(1+Assumptions!B39)^(26-1) -> 2166941.2 | AB26: =Assumptions!B38*(1+Assumptions!B39)^(27-1) -> 2383635.3 | AC26: =Assumptions!B38*(1+Assumptions!B39)^(28-1) -> 2621998.8 | AD26: =Assumptions!B38*(1+Assumptions!B39)^(29-1) -> 2884198.7 | AE26: =Assumptions!B38*(1+Assumptions!B39)^(30-1) -> 3172618.6 | AF26: =Assumptions!B38*(1+Assumptions!B39)^(31-1) -> 3489880.5 | AG26: =Assumptions!B38*(1+Assumptions!B39)^(32-1) -> 3838868.5 | AH26: =Assumptions!B38*(1+Assumptions!B39)^(33-1) -> 4222755.3 | AI26: =Assumptions!B38*(1+Assumptions!B39)^(34-1) -> 4645030.9 | AJ26: =Assumptions!B38*(1+Assumptions!B39)^(35-1) -> 5109534 | AK26: =Assumptions!B38*(1+Assumptions!B39)^(36-1) -> 5620487.4
A27: Payment processing (on passthrough) | B27: =(B14+B18)*Assumptions!B40 -> 11250 | C27: =(C14+C18)*Assumptions!B40 -> 13905 | D27: =(D14+D18)*Assumptions!B40 -> 19096.2 | E27: =(E14+E18)*Assumptions!B40 -> 24586.35 | F27: =(F14+F18)*Assumptions!B40 -> 32921.07 | G27: =(G14+G18)*Assumptions!B40 -> 41733.84 | H27: =(H14+H18)*Assumptions!B40 -> 51045.78 | I27: =(I14+I18)*Assumptions!B40 -> 60878.73 | J27: =(J14+J18)*Assumptions!B40 -> 71256 | K27: =(K14+K18)*Assumptions!B40 -> 85886.46 | L27: =(L14+L18)*Assumptions!B40 -> 103596.87 | M27: =(M14+M18)*Assumptions!B40 -> 125407.88 | N27: =(N14+N18)*Assumptions!B40 -> 146094.64 | O27: =(O14+O18)*Assumptions!B40 -> 170337.46 | P27: =(P14+P18)*Assumptions!B40 -> 195903.66 | Q27: =(Q14+Q18)*Assumptions!B40 -> 226357.34 | R27: =(R14+R18)*Assumptions!B40 -> 263128.46 | S27: =(S14+S18)*Assumptions!B40 -> 304555.58 | T27: =(T14+T18)*Assumptions!B40 -> 352063.71 | U27: =(U14+U18)*Assumptions!B40 -> 406094.79 | V27: =(V14+V18)*Assumptions!B40 -> 468399.09 | W27: =(W14+W18)*Assumptions!B40 -> 541152.05 | X27: =(X14+X18)*Assumptions!B40 -> 622164.27 | Y27: =(Y14+Y18)*Assumptions!B40 -> 716430.99 | Z27: =(Z14+Z18)*Assumptions!B40 -> 788354.02 | AA27: =(AA14+AA18)*Assumptions!B40 -> 868662.54 | AB27: =(AB14+AB18)*Assumptions!B40 -> 957933.71 | AC27: =(AC14+AC18)*Assumptions!B40 -> 1056777.8 | AD27: =(AD14+AD18)*Assumptions!B40 -> 1165843.7 | AE27: =(AE14+AE18)*Assumptions!B40 -> 1285808.2 | AF27: =(AF14+AF18)*Assumptions!B40 -> 1417382.3 | AG27: =(AG14+AG18)*Assumptions!B40 -> 1561325.5 | AH27: =(AH14+AH18)*Assumptions!B40 -> 1724217.9 | AI27: =(AI14+AI18)*Assumptions!B40 -> 1901452 | AJ27: =(AJ14+AJ18)*Assumptions!B40 -> 2093920.9 | AK27: =(AK14+AK18)*Assumptions!B40 -> 2308887.2
A28: Other OpEx | B28: =Assumptions!B41*(1+Assumptions!B42)^(1-1) -> 300000 | C28: =Assumptions!B41*(1+Assumptions!B42)^(2-1) -> 315000 | D28: =Assumptions!B41*(1+Assumptions!B42)^(3-1) -> 330750 | E28: =Assumptions!B41*(1+Assumptions!B42)^(4-1) -> 347287.5 | F28: =Assumptions!B41*(1+Assumptions!B42)^(5-1) -> 364651.88 | G28: =Assumptions!B41*(1+Assumptions!B42)^(6-1) -> 382884.47 | H28: =Assumptions!B41*(1+Assumptions!B42)^(7-1) -> 402028.69 | I28: =Assumptions!B41*(1+Assumptions!B42)^(8-1) -> 422130.13 | J28: =Assumptions!B41*(1+Assumptions!B42)^(9-1) -> 443236.63 | K28: =Assumptions!B41*(1+Assumptions!B42)^(10-1) -> 465398.46 | L28: =Assumptions!B41*(1+Assumptions!B42)^(11-1) -> 488668.39 | M28: =Assumptions!B41*(1+Assumptions!B42)^(12-1) -> 513101.81 | N28: =Assumptions!B41*(1+Assumptions!B42)^(13-1) -> 538756.9 | O28: =Assumptions!B41*(1+Assumptions!B42)^(14-1) -> 565694.74 | P28: =Assumptions!B41*(1+Assumptions!B42)^(15-1) -> 593979.48 | Q28: =Assumptions!B41*(1+Assumptions!B42)^(16-1) -> 623678.45 | R28: =Assumptions!B41*(1+Assumptions!B42)^(17-1) -> 654862.38 | S28: =Assumptions!B41*(1+Assumptions!B42)^(18-1) -> 687605.5 | T28: =Assumptions!B41*(1+Assumptions!B42)^(19-1) -> 721985.77 | U28: =Assumptions!B41*(1+Assumptions!B42)^(20-1) -> 758085.06 | V28: =Assumptions!B41*(1+Assumptions!B42)^(21-1) -> 795989.31 | W28: =Assumptions!B41*(1+Assumptions!B42)^(22-1) -> 835788.78 | X28: =Assumptions!B41*(1+Assumptions!B42)^(23-1) -> 877578.22 | Y28: =Assumptions!B41*(1+Assumptions!B42)^(24-1) -> 921457.13 | Z28: =Assumptions!B41*(1+Assumptions!B42)^(25-1) -> 967529.98 | AA28: =Assumptions!B41*(1+Assumptions!B42)^(26-1) -> 1015906.5 | AB28: =Assumptions!B41*(1+Assumptions!B42)^(27-1) -> 1066701.8 | AC28: =Assumptions!B41*(1+Assumptions!B42)^(28-1) -> 1120036.9 | AD28: =Assumptions!B41*(1+Assumptions!B42)^(29-1) -> 1176038.7 | AE28: =Assumptions!B41*(1+Assumptions!B42)^(30-1) -> 1234840.7 | AF28: =Assumptions!B41*(1+Assumptions!B42)^(31-1) -> 1296582.7 | AG28: =Assumptions!B41*(1+Assumptions!B42)^(32-1) -> 1361411.8 | AH28: =Assumptions!B41*(1+Assumptions!B42)^(33-1) -> 1429482.4 | AI28: =Assumptions!B41*(1+Assumptions!B42)^(34-1) -> 1500956.6 | AJ28: =Assumptions!B41*(1+Assumptions!B42)^(35-1) -> 1576004.4 | AK28: =Assumptions!B41*(1+Assumptions!B42)^(36-1) -> 1654804.6
A29: Total Costs | B29: =SUM(B24:B28) -> 4911250 | C29: =SUM(C24:C28) -> 5012905 | D29: =SUM(D24:D28) -> 5124966.2 | E29: =SUM(E24:E28) -> 5245843.5 | F29: =SUM(F24:F28) -> 6578784.1 | G29: =SUM(G24:G28) -> 6722182.8 | H29: =SUM(H24:H28) -> 6876886.1 | I29: =SUM(I24:I28) -> 7043811.7 | ... AK29: =SUM(AK24:AK28) -> 34612455
A32: EBITDA / PROFIT
A33: EBITDA (Revenue - Costs) | B33: =B21-B29 -> -4828750 | C33: =C21-C29 -> -4910935 | D33: =D21-D29 -> -4984927.4 | E33: =E21-E29 -> -5065543.5 | F33: =F21-F29 -> -6337362.9 | G33: =G21-G29 -> -6416134.6 | H33: =H21-H29 -> -6502550.4 | I33: =I21-I29 -> -6597367.7 | ... AK33: =AK21-AK29 -> -17492395
A34: EBITDA Margin | B34: =IF(B21>0,B33/B21,0) -> -58.530303 | C34: =IF(C21>0,C33/C21,0) -> -48.160586 | D34: =IF(D21>0,D33/D21,0) -> -35.596759 | E34: =IF(E21>0,E33/E21,0) -> -28.095099 | F34: =IF(F21>0,F33/F21,0) -> -26.250236 | G34: =IF(G21>0,G33/G21,0) -> -20.964461 | H34: =IF(H21>0,H33/H21,0) -> -17.370905 | I34: =IF(I21>0,I33/I21,0) -> -14.777592 | ... AK34: =IF(AK21>0,AK33/AK21,0) -> -1.0217484
A35: Cumulative EBITDA | B35: =B33 -> -4828750 | C35: =B35+C33 -> -9739685 | D35: =C35+D33 -> -14724612 | E35: =D35+E33 -> -19790156 | F35: =E35+F33 -> -26127519 | G35: =F35+G33 -> -32543653 | H35: =G35+H33 -> -39046204 | I35: =H35+I33 -> -45643572 | J35: =I35+J33 -> -53544982 | ... AK35: =AJ35+AK33 -> -3.9854788e+08
A37: CASH
A38: Fundraising inflow | B38: =Assumptions!B48 -> 50000000 | C38: =IF(2=Assumptions!B50,Assumptions!B49,0) -> 0 | D38: =IF(3=Assumptions!B50,Assumptions!B49,0) -> 0 | E38: =IF(4=Assumptions!B50,Assumptions!B49,0) -> 0 | F38: =IF(5=Assumptions!B50,Assumptions!B49,0) -> 0 | G38: =IF(6=Assumptions!B50,Assumptions!B49,0) -> 0 | H38: =IF(7=Assumptions!B50,Assumptions!B49,0) -> 0 | I38: =IF(8=Assumptions!B50,Assumptions!B49,0) -> 400000000 | J38: =IF(9=Assumptions!B50,Assumptions!B49,0) -> 0 | K38: =IF(10=Assumptions!B50,Assumptions!B49,0) -> 0 | L38: =IF(11=Assumptions!B50,Assumptions!B49,0) -> 0 | M38: =IF(12=Assumptions!B50,Assumptions!B49,0) -> 0 | N38: =IF(13=Assumptions!B50,Assumptions!B49,0) -> 0 | O38: =IF(14=Assumptions!B50,Assumptions!B49,0) -> 0 | P38: =IF(15=Assumptions!B50,Assumptions!B49,0) -> 0 | Q38: =IF(16=Assumptions!B50,Assumptions!B49,0) -> 0 | R38: =IF(17=Assumptions!B50,Assumptions!B49,0) -> 0 | S38: =IF(18=Assumptions!B50,Assumptions!B49,0) -> 0 | T38: =IF(19=Assumptions!B50,Assumptions!B49,0) -> 0 | U38: =IF(20=Assumptions!B50,Assumptions!B49,0) -> 0 | V38: =IF(21=Assumptions!B50,Assumptions!B49,0) -> 0 | W38: =IF(22=Assumptions!B50,Assumptions!B49,0) -> 0 | X38: =IF(23=Assumptions!B50,Assumptions!B49,0) -> 0 | Y38: =IF(24=Assumptions!B50,Assumptions!B49,0) -> 0 | Z38: =IF(25=Assumptions!B50,Assumptions!B49,0) -> 0 | AA38: =IF(26=Assumptions!B50,Assumptions!B49,0) -> 0 | AB38: =IF(27=Assumptions!B50,Assumptions!B49,0) -> 0 | AC38: =IF(28=Assumptions!B50,Assumptions!B49,0) -> 0 | AD38: =IF(29=Assumptions!B50,Assumptions!B49,0) -> 0 | AE38: =IF(30=Assumptions!B50,Assumptions!B49,0) -> 0 | AF38: =IF(31=Assumptions!B50,Assumptions!B49,0) -> 0 | AG38: =IF(32=Assumptions!B50,Assumptions!B49,0) -> 0 | AH38: =IF(33=Assumptions!B50,Assumptions!B49,0) -> 0 | AI38: =IF(34=Assumptions!B50,Assumptions!B49,0) -> 0 | AJ38: =IF(35=Assumptions!B50,Assumptions!B49,0) -> 0 | AK38: =IF(36=Assumptions!B50,Assumptions!B49,0) -> 0
A39: Cash balance | B39: =B38+B33 -> 45171250 | C39: =B39+C38+C33 -> 40260315 | D39: =C39+D38+D33 -> 35275388 | E39: =D39+E38+E33 -> 30209844 | F39: =E39+F38+F33 -> 23872481 | G39: =F39+G38+G33 -> 17456347 | H39: =G39+H38+H33 -> 10953796 | I39: =H39+I38+I33 -> 4.0435643e+08 | J39: =I39+J38+J33 -> 3.9645502e+08 | ... AK39: =AJ39+AK38+AK33 -> 51452121
A40: Runway (months at current burn) | B40: =IF(B33<0,B39/ABS(B33),"∞") -> 9.3546466 | C40: =IF(C33<0,C39/ABS(C33),"∞") -> 8.1980957 | D40: =IF(D33<0,D39/ABS(D33),"∞") -> 7.0764095 | E40: =IF(E33<0,E39/ABS(E33),"∞") -> 5.9637912 | F40: =IF(F33<0,F39/ABS(F33),"∞") -> 3.7669424 | G40: =IF(G33<0,G39/ABS(G33),"∞") -> 2.7206952 | H40: =IF(H33<0,H39/ABS(H33),"∞") -> 1.6845384 | I40: =IF(I33<0,I39/ABS(I33),"∞") -> 61.290571 | ... AK40: =IF(AK33<0,AK39/ABS(AK33),"∞") -> 2.9413995
A42: KEY METRICS
A43: Revenue per customer (₦) | B43: =IF(B9>0,B21/B9,0) -> 16500 | C43: =IF(C9>0,C21/C9,0) -> 16995 | D43: =IF(D9>0,D21/D9,0) -> 17504.85 | E43: =IF(E9>0,E21/E9,0) -> 18029.99 | F43: =IF(F9>0,F21/F9,0) -> 18570.86 | G43: =IF(G9>0,G21/G9,0) -> 19128.01 | H43: =IF(H9>0,H21/H9,0) -> 19701.88 | I43: =IF(I9>0,I21/I9,0) -> 20292.91 | ... AK43: =IF(AK9>0,AK21/AK9,0) -> 47162.699
A44: Gross margin | B44: =IF(B21>0,(B21-B27)/B21,0) -> 0.86363636 | C44: =IF(C21>0,(C21-C27)/C21,0) -> 0.86363636 | D44: =IF(D21>0,(D21-D27)/D21,0) -> 0.86363636 | E44: =IF(E21>0,(E21-E27)/E21,0) -> 0.86363636 | F44: =IF(F21>0,(F21-F27)/F21,0) -> 0.86363636 | G44: =IF(G21>0,(G21-G27)/G21,0) -> 0.86363636 | H44: =IF(H21>0,(H21-H27)/H21,0) -> 0.86363636 | I44: =IF(I21>0,(I21-I27)/I21,0) -> 0.86363636 | ... AK44: =IF(AK21>0,(AK21-AK27)/AK21,0) -> 0.86513557
A45: Team size | B45: =Assumptions!B35+INT((1-1)/Assumptions!B37) -> 3 | C45: =Assumptions!B35+INT((2-1)/Assumptions!B37) -> 3 | D45: =Assumptions!B35+INT((3-1)/Assumptions!B37) -> 3 | E45: =Assumptions!B35+INT((4-1)/Assumptions!B37) -> 3 | F45: =Assumptions!B35+INT((5-1)/Assumptions!B37) -> 4 | G45: =Assumptions!B35+INT((6-1)/Assumptions!B37) -> 4 | H45: =Assumptions!B35+INT((7-1)/Assumptions!B37) -> 4 | I45: =Assumptions!B35+INT((8-1)/Assumptions!B37) -> 4 | J45: =Assumptions!B35+INT((9-1)/Assumptions!B37) -> 5 | K45: =Assumptions!B35+INT((10-1)/Assumptions!B37) -> 5 | L45: =Assumptions!B35+INT((11-1)/Assumptions!B37) -> 5 | M45: =Assumptions!B35+INT((12-1)/Assumptions!B37) -> 5 | N45: =Assumptions!B35+INT((13-1)/Assumptions!B37) -> 6 | O45: =Assumptions!B35+INT((14-1)/Assumptions!B37) -> 6 | P45: =Assumptions!B35+INT((15-1)/Assumptions!B37) -> 6 | Q45: =Assumptions!B35+INT((16-1)/Assumptions!B37) -> 6 | R45: =Assumptions!B35+INT((17-1)/Assumptions!B37) -> 7 | S45: =Assumptions!B35+INT((18-1)/Assumptions!B37) -> 7 | T45: =Assumptions!B35+INT((19-1)/Assumptions!B37) -> 7 | U45: =Assumptions!B35+INT((20-1)/Assumptions!B37) -> 7 | V45: =Assumptions!B35+INT((21-1)/Assumptions!B37) -> 8 | W45: =Assumptions!B35+INT((22-1)/Assumptions!B37) -> 8 | X45: =Assumptions!B35+INT((23-1)/Assumptions!B37) -> 8 | Y45: =Assumptions!B35+INT((24-1)/Assumptions!B37) -> 8 | Z45: =Assumptions!B35+INT((25-1)/Assumptions!B37) -> 9 | AA45: =Assumptions!B35+INT((26-1)/Assumptions!B37) -> 9 | AB45: =Assumptions!B35+INT((27-1)/Assumptions!B37) -> 9 | AC45: =Assumptions!B35+INT((28-1)/Assumptions!B37) -> 9 | AD45: =Assumptions!B35+INT((29-1)/Assumptions!B37) -> 10 | AE45: =Assumptions!B35+INT((30-1)/Assumptions!B37) -> 10 | AF45: =Assumptions!B35+INT((31-1)/Assumptions!B37) -> 10 | AG45: =Assumptions!B35+INT((32-1)/Assumptions!B37) -> 10 | AH45: =Assumptions!B35+INT((33-1)/Assumptions!B37) -> 11 | AI45: =Assumptions!B35+INT((34-1)/Assumptions!B37) -> 11 | AJ45: =Assumptions!B35+INT((35-1)/Assumptions!B37) -> 11 | AK45: =Assumptions!B35+INT((36-1)/Assumptions!B37) -> 11
A46: Revenue per employee (₦) | B46: =IF(B45>0,B21/B45,0) -> 27500 | C46: =IF(C45>0,C21/C45,0) -> 33990 | D46: =IF(D45>0,D21/D45,0) -> 46679.6 | E46: =IF(E45>0,E21/E45,0) -> 60099.967 | F46: =IF(F45>0,F21/F45,0) -> 60355.295 | G46: =IF(G45>0,G21/G45,0) -> 76512.04 | H46: =IF(H45>0,H21/H45,0) -> 93583.93 | I46: =IF(I45>0,I21/I45,0) -> 111611.01 | ... AK46: =IF(AK45>0,AK21/AK45,0) -> 1556369.1
A47: Revenue (USD equivalent) | B47: =B21/Assumptions!B45 -> 51.5625 | C47: =C21/Assumptions!B45 -> 63.73125 | D47: =D21/Assumptions!B45 -> 87.52425 | E47: =E21/Assumptions!B45 -> 112.68744 | F47: =F21/Assumptions!B45 -> 150.88824 | G47: =G21/Assumptions!B45 -> 191.2801 | H47: =H21/Assumptions!B45 -> 233.95982 | I47: =I21/Assumptions!B45 -> 279.02751 | J47: =J21/Assumptions!B45 -> 326.59 | K47: =K21/Assumptions!B45 -> 397.13918 | L47: =L21/Assumptions!B45 -> 479.32504 | M47: =M21/Assumptions!B45 -> 580.5569 | N47: =N21/Assumptions!B45 -> 674.39024 | O47: =O21/Assumptions!B45 -> 786.8013 | P47: =P21/Assumptions!B45 -> 905.34971 | Q47: =Q21/Assumptions!B45 -> 1046.5931 | R47: =R21/Assumptions!B45 -> 1214.536 | S47: =S21/Assumptions!B45 -> 1406.6038 | T47: =T21/Assumptions!B45 -> 1626.9031 | U47: =U21/Assumptions!B45 -> 1877.4862 | V47: =V21/Assumptions!B45 -> 2163.2766 | W47: =W21/Assumptions!B45 -> 2500.6333 | X47: =X21/Assumptions!B45 -> 2876.3291 | Y47: =Y21/Assumptions!B45 -> 3313.5695 | Z47: =Z21/Assumptions!B45 -> 3646.9694 | AA47: =AA21/Assumptions!B45 -> 4019.2898 | AB47: =AB21/Assumptions!B45 -> 4433.2102 | AC47: =AC21/Assumptions!B45 -> 4891.5639 | AD47: =AD21/Assumptions!B45 -> 5397.3635 | AE47: =AE21/Assumptions!B45 -> 5953.7507 | AF47: =AF21/Assumptions!B45 -> 6564.0273 | AG47: =AG21/Assumptions!B45 -> 7231.7184 | AH47: =AH21/Assumptions!B45 -> 7987.3923 | AI47: =AI21/Assumptions!B45 -> 8809.6411 | AJ47: =AJ21/Assumptions!B45 -> 9702.6097 | AK47: =AK21/Assumptions!B45 -> 10700.037

Sheet Annual Summary
A1: Mazou — Annual Summary
A2: All values in ₦ unless noted
B4: Year 1 (M1-12) | C4: Year 2 (M13-24) | D4: Year 3 (M25-36)
A6: CUSTOMERS
A7: End-of-year customers | B7: ='Monthly P&L'!M9 -> 40 | C7: ='Monthly P&L'!Y9 -> 160 | D7: ='Monthly P&L'!AK9 -> 363
A8: Avg monthly customers | B8: =ROUND(AVERAGE('Monthly P&L'!B9:M9),0) -> 19 | C8: =ROUND(AVERAGE('Monthly P&L'!N9:Y9),0) -> 92 | D8: =ROUND(AVERAGE('Monthly P&L'!Z9:AK9),0) -> 256
A9: Agent service adopters (EoY) | B9: ='Monthly P&L'!M10 -> 1 | C9: ='Monthly P&L'!Y10 -> 4 | D9: ='Monthly P&L'!AK10 -> 4
A11: REVENUE
A12: LLM take rate revenue | B12: =SUM('Monthly P&L'!B15:M15) -> 3409065.6 | C12: =SUM('Monthly P&L'!N15:Y15) -> 23303662 | D12: =SUM('Monthly P&L'!Z15:AK15) -> 90833568
A13: Routing savings share | B13: =SUM('Monthly P&L'!B17:M17) -> 1278399.6 | C13: =SUM('Monthly P&L'!N17:Y17) -> 8738873.4 | D13: =SUM('Monthly P&L'!Z17:AK17) -> 34062588
A14: Agent services revenue | B14: =SUM('Monthly P&L'!B19:M19) -> 7881.25 | C14: =SUM('Monthly P&L'!N19:Y19) -> 144151.15 | D14: =SUM('Monthly P&L'!Z19:AK19) -> 330905.63
A15: USDT FX revenue | B15: =SUM('Monthly P&L'!B20:M20) -> 31489.121 | C15: =SUM('Monthly P&L'!N20:Y20) -> 441268.2 | D15: =SUM('Monthly P&L'!Z20:AK20) -> 1713056.6
A16: Total Revenue | B16: =SUM(B12:B15) -> 4726835.6 | C16: =SUM(C12:C15) -> 32627955 | D16: =SUM(D12:D15) -> 1.2694012e+08
A18: COSTS
A19: Infrastructure | B19: =SUM('Monthly P&L'!B24:M24) -> 15181701 | C19: =SUM('Monthly P&L'!N24:Y24) -> 38230106 | D19: =SUM('Monthly P&L'!Z24:AK24) -> 96269911
A20: Team | B20: =SUM('Monthly P&L'!B25:M25) -> 57600000 | C20: =SUM('Monthly P&L'!N25:Y25) -> 100800000 | D20: =SUM('Monthly P&L'!Z25:AK25) -> 144000000
A21: Marketing | B21: =SUM('Monthly P&L'!B26:M26) -> 4276856.8 | C21: =SUM('Monthly P&L'!N26:Y26) -> 13422609 | D21: =SUM('Monthly P&L'!Z26:AK26) -> 42125896
A22: Payment processing | B22: =SUM('Monthly P&L'!B27:M27) -> 641564.18 | C22: =SUM('Monthly P&L'!N27:Y27) -> 4412682 | D22: =SUM('Monthly P&L'!Z27:AK27) -> 17130566
A23: Other OpEx | B23: =SUM('Monthly P&L'!B28:M28) -> 4775138 | C23: =SUM('Monthly P&L'!N28:Y28) -> 8575461.7 | D23: =SUM('Monthly P&L'!Z28:AK28) -> 15400297
A24: Total Costs
A25: Total Costs | B25: =SUM(B19:B24) -> 82475260 | C25: =SUM(C19:C24) -> 1.6544086e+08 | D25: =SUM(D19:D24) -> 3.1492667e+08
A27: PROFITABILITY
A28: EBITDA | B28: =B16-B25 -> -77748424 | C28: =C16-C25 -> -1.328129e+08 | D28: =D16-D25 -> -1.8798655e+08
A29: EBITDA Margin | B29: =IF(B16>0,B28/B16,0) -> -16.448303 | C29: =IF(C16>0,C28/C16,0) -> -4.0705249 | D29: =IF(D16>0,D28/D16,0) -> -1.4809073
A30: EBITDA (USD) | B30: =B28/Assumptions!B45 -> -48592.765 | C30: =C28/Assumptions!B45 -> -83008.065 | D30: =D28/Assumptions!B45 -> -117491.59
A32: CASH
A33: End-of-year cash | B33: ='Monthly P&L'!M39 -> 3.7225158e+08 | C33: ='Monthly P&L'!Y39 -> 2.3943867e+08 | D33: ='Monthly P&L'!AK39 -> 51452121
A34: End-of-year cash (USD) | B34: =B33/Assumptions!B45 -> 232657.23 | C34: =C33/Assumptions!B45 -> 149649.17 | D34: =D33/Assumptions!B45 -> 32157.576

Sheet Unit Economics
A1: Mazou — Unit Economics
A2: Key SaaS / infrastructure metrics
B4: Year 1 | C4: Year 2 | D4: Year 3
A6: REVENUE METRICS
A7: Annual Revenue (₦) | B7: ='Annual Summary'!B16 -> 4726835.6 | C7: ='Annual Summary'!C16 -> 32627955 | D7: ='Annual Summary'!D16 -> 1.2694012e+08
A8: Annual Revenue (USD) | B8: =B7/Assumptions!B45 -> 2954.2722 | C8: =C7/Assumptions!B45 -> 20392.472 | D8: =D7/Assumptions!B45 -> 79337.574
A9: MRR End of Year (₦) | B9: ='Monthly P&L'!M21 -> 928891.04 | C9: ='Monthly P&L'!Y21 -> 5301711.2 | D9: ='Monthly P&L'!AK21 -> 17120060
A10: ARR End of Year (₦) | B10: =B9*12 -> 11146692 | C10: =C9*12 -> 63620535 | D10: =D9*12 -> 2.0544072e+08
A12: PER-CUSTOMER METRICS
A13: Avg Revenue Per Customer (₦/mo) | B13: =IF('Annual Summary'!B8>0,B7/12/'Annual Summary'!B8,0) -> 20731.735 | C13: =IF('Annual Summary'!C8>0,C7/12/'Annual Summary'!C8,0) -> 29554.307 | D13: =IF('Annual Summary'!D8>0,D7/12/'Annual Summary'!D8,0) -> 41321.653
A14: Avg Revenue Per Customer (USD/mo) | B14: =B13/Assumptions!B45 -> 12.957334 | C14: =C13/Assumptions!B45 -> 18.471442 | D14: =D13/Assumptions!B45 -> 25.826033
A15: LLM revenue per customer | B15: =IF('Annual Summary'!B8>0,('Annual Summary'!B12+'Annual Summary'!B13)/12/'Annual Summary'!B8,0) -> 20559.058 | C15: =IF('Annual Summary'!C8>0,('Annual Summary'!C12+'Annual Summary'!C13)/12/'Annual Summary'!C8,0) -> 29024.036 | D15: =IF('Annual Summary'!D8>0,('Annual Summary'!D12+'Annual Summary'!D13)/12/'Annual Summary'!D8,0) -> 40656.301
A16: Agent service revenue per adopter | B16: =IF('Annual Summary'!B9>0,'Annual Summary'!B14/12/'Annual Summary'!B9,0) -> 656.77083 | C16: =IF('Annual Summary'!C9>0,'Annual Summary'!C14/12/'Annual Summary'!C9,0) -> 3003.1489 | D16: =IF('Annual Summary'!D9>0,'Annual Summary'!D14/12/'Annual Summary'!D9,0) -> 6893.8673
A18: MARGINS
A19: Gross Margin (after API + processing) | B19: =IF('Annual Summary'!B16>0,('Annual Summary'!B16-'Annual Summary'!B22)/'Annual Summary'!B16,0) -> 0.86427195 | C19: =IF('Annual Summary'!C16>0,('Annual Summary'!C16-'Annual Summary'!C22)/'Annual Summary'!C16,0) -> 0.86475763 | D19: =IF('Annual Summary'!D16>0,('Annual Summary'!D16-'Annual Summary'!D22)/'Annual Summary'!D16,0) -> 0.86505003
A20: EBITDA Margin | B20: ='Annual Summary'!B29 -> -16.448303 | C20: ='Annual Summary'!C29 -> -4.0705249 | D20: ='Annual Summary'!D29 -> -1.4809073
A21: Net Revenue Retention | B21: =(1+Assumptions!B14)^12*(1-Assumptions!B10)^12 -> 0.9892533 | C21: =(1+Assumptions!B14)^12*(1-Assumptions!B10)^12 -> 0.9892533 | D21: =(1+Assumptions!B14)^12*(1-Assumptions!B10)^12 -> 0.9892533
A23: GROWTH
A24: Revenue growth (YoY) | B24: N/A | C24: =IF(B7>0,(C7-B7)/B7,0) -> 5.9027058 | D24: =IF(C7>0,(D7-C7)/C7,0) -> 2.8905325
A25: Customer growth (YoY) | B25: N/A | C25: =IF('Annual Summary'!B7>0,('Annual Summary'!C7-'Annual Summary'!B7)/'Annual Summary'!B7,0) -> 3 | D25: =IF('Annual Summary'!C7>0,('Annual Summary'!D7-'Annual Summary'!C7)/'Annual Summary'!C7,0) -> 1.26875
A27: UNIT ECONOMICS
A28: Implied CAC (marketing / new customers) | B28: =IF(SUM('Monthly P&L'!B7:M7)>0,'Annual Summary'!B22/SUM('Monthly P&L'!B7:M7),0) -> 14256.982 | C28: =IF(SUM('Monthly P&L'!N7:Y7)>0,'Annual Summary'!C22/SUM('Monthly P&L'!N7:Y7),0) -> 29615.316 | D28: =IF(SUM('Monthly P&L'!Z7:AK7)>0,'Annual Summary'!D22/SUM('Monthly P&L'!Z7:AK7),0) -> 59275.314
A29: Implied LTV (12mo rev × gross margin) | B29: =IF(Assumptions!B10>0,B13*B19/Assumptions!B10,0) -> 597261.9 | C29: =IF(Assumptions!B10>0,C13*C19/Assumptions!B10,0) -> 851910.42 | D29: =IF(Assumptions!B10>0,D13*D19/Assumptions!B10,0) -> 1191509.9
A30: LTV / CAC | B30: =IF(B28>0,B29/B28,0) -> 41.892591 | C30: =IF(C28>0,C29/C28,0) -> 28.765873 | D30: =IF(D28>0,D29/D28,0) -> 20.101284
